[2025-07-21T14:39:29.058+0000] {taskinstance.py:1956} INFO - Dependencies all met for dep_context=non-requeueable deps ti=<TaskInstance: put_data_to_db.insert_to_db manual__2025-07-21T14:39:25.513360+00:00 [queued]>
[2025-07-21T14:39:29.068+0000] {taskinstance.py:1956} INFO - Dependencies all met for dep_context=requeueable deps ti=<TaskInstance: put_data_to_db.insert_to_db manual__2025-07-21T14:39:25.513360+00:00 [queued]>
[2025-07-21T14:39:29.069+0000] {taskinstance.py:2170} INFO - Starting attempt 1 of 1
[2025-07-21T14:39:29.085+0000] {taskinstance.py:2191} INFO - Executing <Task(PythonOperator): insert_to_db> on 2025-07-21 14:39:25.513360+00:00
[2025-07-21T14:39:29.089+0000] {standard_task_runner.py:60} INFO - Started process 461 to run task
[2025-07-21T14:39:29.091+0000] {standard_task_runner.py:87} INFO - Running: ['***', 'tasks', 'run', 'put_data_to_db', 'insert_to_db', 'manual__2025-07-21T14:39:25.513360+00:00', '--job-id', '11', '--raw', '--subdir', 'DAGS_FOLDER/__pycache__/get_data_to_db.py', '--cfg-path', '/tmp/tmpq230ag19']
[2025-07-21T14:39:29.094+0000] {standard_task_runner.py:88} INFO - Job 11: Subtask insert_to_db
[2025-07-21T14:39:29.142+0000] {task_command.py:423} INFO - Running <TaskInstance: put_data_to_db.insert_to_db manual__2025-07-21T14:39:25.513360+00:00 [running]> on host d7e7273683d1
[2025-07-21T14:39:29.223+0000] {taskinstance.py:2480} INFO - Exporting env vars: AIRFLOW_CTX_DAG_OWNER='***' AIRFLOW_CTX_DAG_ID='put_data_to_db' AIRFLOW_CTX_TASK_ID='insert_to_db' AIRFLOW_CTX_EXECUTION_DATE='2025-07-21T14:39:25.513360+00:00' AIRFLOW_CTX_TRY_NUMBER='1' AIRFLOW_CTX_DAG_RUN_ID='manual__2025-07-21T14:39:25.513360+00:00'
[2025-07-21T14:39:29.234+0000] {taskinstance.py:2698} ERROR - Task failed with exception
Traceback (most recent call last):
  File "/home/airflow/.local/lib/python3.8/site-packages/airflow/models/taskinstance.py", line 433, in _execute_task
    result = execute_callable(context=context, **execute_callable_kwargs)
  File "/home/airflow/.local/lib/python3.8/site-packages/airflow/operators/python.py", line 199, in execute
    return_value = self.execute_callable()
  File "/home/airflow/.local/lib/python3.8/site-packages/airflow/operators/python.py", line 216, in execute_callable
    return self.python_callable(*self.op_args, **self.op_kwargs)
  File "/opt/airflow/dags/__pycache__/get_data_to_db.py", line 54, in insert_to_db
    conn = psycopg2.connect(
  File "/home/airflow/.local/lib/python3.8/site-packages/psycopg2/__init__.py", line 122, in connect
    conn = _connect(dsn, connection_factory=connection_factory, **kwasync)
psycopg2.OperationalError: connection to server at "localhost" (::1), port 5432 failed: Connection refused
	Is the server running on that host and accepting TCP/IP connections?
connection to server at "localhost" (127.0.0.1), port 5432 failed: Connection refused
	Is the server running on that host and accepting TCP/IP connections?

[2025-07-21T14:39:29.247+0000] {taskinstance.py:1138} INFO - Marking task as FAILED. dag_id=put_data_to_db, task_id=insert_to_db, execution_date=20250721T143925, start_date=20250721T143929, end_date=20250721T143929
[2025-07-21T14:39:29.260+0000] {standard_task_runner.py:107} ERROR - Failed to execute job 11 for task insert_to_db (connection to server at "localhost" (::1), port 5432 failed: Connection refused
	Is the server running on that host and accepting TCP/IP connections?
connection to server at "localhost" (127.0.0.1), port 5432 failed: Connection refused
	Is the server running on that host and accepting TCP/IP connections?
; 461)
[2025-07-21T14:39:29.305+0000] {local_task_job_runner.py:234} INFO - Task exited with return code 1
[2025-07-21T14:39:29.323+0000] {taskinstance.py:3280} INFO - 0 downstream tasks scheduled from follow-on schedule check
