[2025-07-21T14:52:56.084+0000] {taskinstance.py:1956} INFO - Dependencies all met for dep_context=non-requeueable deps ti=<TaskInstance: put_data_to_db.insert_to_db manual__2025-07-21T14:52:54.026981+00:00 [queued]>
[2025-07-21T14:52:56.094+0000] {taskinstance.py:1956} INFO - Dependencies all met for dep_context=requeueable deps ti=<TaskInstance: put_data_to_db.insert_to_db manual__2025-07-21T14:52:54.026981+00:00 [queued]>
[2025-07-21T14:52:56.095+0000] {taskinstance.py:2170} INFO - Starting attempt 1 of 1
[2025-07-21T14:52:56.109+0000] {taskinstance.py:2191} INFO - Executing <Task(PythonOperator): insert_to_db> on 2025-07-21 14:52:54.026981+00:00
[2025-07-21T14:52:56.113+0000] {standard_task_runner.py:60} INFO - Started process 234 to run task
[2025-07-21T14:52:56.117+0000] {standard_task_runner.py:87} INFO - Running: ['***', 'tasks', 'run', 'put_data_to_db', 'insert_to_db', 'manual__2025-07-21T14:52:54.026981+00:00', '--job-id', '4', '--raw', '--subdir', 'DAGS_FOLDER/__pycache__/get_data_to_db.py', '--cfg-path', '/tmp/tmpax2ns7en']
[2025-07-21T14:52:56.119+0000] {standard_task_runner.py:88} INFO - Job 4: Subtask insert_to_db
[2025-07-21T14:52:56.165+0000] {task_command.py:423} INFO - Running <TaskInstance: put_data_to_db.insert_to_db manual__2025-07-21T14:52:54.026981+00:00 [running]> on host 01a72dbe7648
[2025-07-21T14:52:56.236+0000] {taskinstance.py:2480} INFO - Exporting env vars: AIRFLOW_CTX_DAG_OWNER='***' AIRFLOW_CTX_DAG_ID='put_data_to_db' AIRFLOW_CTX_TASK_ID='insert_to_db' AIRFLOW_CTX_EXECUTION_DATE='2025-07-21T14:52:54.026981+00:00' AIRFLOW_CTX_TRY_NUMBER='1' AIRFLOW_CTX_DAG_RUN_ID='manual__2025-07-21T14:52:54.026981+00:00'
[2025-07-21T14:52:56.249+0000] {taskinstance.py:2698} ERROR - Task failed with exception
Traceback (most recent call last):
  File "/home/airflow/.local/lib/python3.8/site-packages/airflow/models/taskinstance.py", line 433, in _execute_task
    result = execute_callable(context=context, **execute_callable_kwargs)
  File "/home/airflow/.local/lib/python3.8/site-packages/airflow/operators/python.py", line 199, in execute
    return_value = self.execute_callable()
  File "/home/airflow/.local/lib/python3.8/site-packages/airflow/operators/python.py", line 216, in execute_callable
    return self.python_callable(*self.op_args, **self.op_kwargs)
  File "/opt/airflow/dags/__pycache__/get_data_to_db.py", line 54, in insert_to_db
    conn = psycopg2.connect(
  File "/home/airflow/.local/lib/python3.8/site-packages/psycopg2/__init__.py", line 122, in connect
    conn = _connect(dsn, connection_factory=connection_factory, **kwasync)
psycopg2.OperationalError: connection to server at "postgres" (192.168.48.2), port 5432 failed: FATAL:  password authentication failed for user "postgres"

[2025-07-21T14:52:56.265+0000] {taskinstance.py:1138} INFO - Marking task as FAILED. dag_id=put_data_to_db, task_id=insert_to_db, execution_date=20250721T145254, start_date=20250721T145256, end_date=20250721T145256
[2025-07-21T14:52:56.278+0000] {standard_task_runner.py:107} ERROR - Failed to execute job 4 for task insert_to_db (connection to server at "postgres" (192.168.48.2), port 5432 failed: FATAL:  password authentication failed for user "postgres"
; 234)
[2025-07-21T14:52:56.289+0000] {local_task_job_runner.py:234} INFO - Task exited with return code 1
[2025-07-21T14:52:56.305+0000] {taskinstance.py:3280} INFO - 0 downstream tasks scheduled from follow-on schedule check
