[2025-07-21T15:04:58.188+0000] {taskinstance.py:1956} INFO - Dependencies all met for dep_context=non-requeueable deps ti=<TaskInstance: put_data_to_db.insert_to_db manual__2025-07-21T15:04:47.605430+00:00 [queued]>
[2025-07-21T15:04:58.225+0000] {taskinstance.py:1956} INFO - Dependencies all met for dep_context=requeueable deps ti=<TaskInstance: put_data_to_db.insert_to_db manual__2025-07-21T15:04:47.605430+00:00 [queued]>
[2025-07-21T15:04:58.226+0000] {taskinstance.py:2170} INFO - Starting attempt 1 of 1
[2025-07-21T15:04:58.262+0000] {taskinstance.py:2191} INFO - Executing <Task(PythonOperator): insert_to_db> on 2025-07-21 15:04:47.605430+00:00
[2025-07-21T15:04:58.273+0000] {standard_task_runner.py:60} INFO - Started process 458 to run task
[2025-07-21T15:04:58.279+0000] {standard_task_runner.py:87} INFO - Running: ['***', 'tasks', 'run', 'put_data_to_db', 'insert_to_db', 'manual__2025-07-21T15:04:47.605430+00:00', '--job-id', '12', '--raw', '--subdir', 'DAGS_FOLDER/__pycache__/get_data_to_db.py', '--cfg-path', '/tmp/tmpuyzk5u0c']
[2025-07-21T15:04:58.285+0000] {standard_task_runner.py:88} INFO - Job 12: Subtask insert_to_db
[2025-07-21T15:04:58.385+0000] {task_command.py:423} INFO - Running <TaskInstance: put_data_to_db.insert_to_db manual__2025-07-21T15:04:47.605430+00:00 [running]> on host 01a72dbe7648
[2025-07-21T15:04:58.563+0000] {taskinstance.py:2480} INFO - Exporting env vars: AIRFLOW_CTX_DAG_OWNER='***' AIRFLOW_CTX_DAG_ID='put_data_to_db' AIRFLOW_CTX_TASK_ID='insert_to_db' AIRFLOW_CTX_EXECUTION_DATE='2025-07-21T15:04:47.605430+00:00' AIRFLOW_CTX_TRY_NUMBER='1' AIRFLOW_CTX_DAG_RUN_ID='manual__2025-07-21T15:04:47.605430+00:00'
[2025-07-21T15:04:58.691+0000] {taskinstance.py:2698} ERROR - Task failed with exception
Traceback (most recent call last):
  File "/home/airflow/.local/lib/python3.8/site-packages/airflow/models/taskinstance.py", line 433, in _execute_task
    result = execute_callable(context=context, **execute_callable_kwargs)
  File "/home/airflow/.local/lib/python3.8/site-packages/airflow/operators/python.py", line 199, in execute
    return_value = self.execute_callable()
  File "/home/airflow/.local/lib/python3.8/site-packages/airflow/operators/python.py", line 216, in execute_callable
    return self.python_callable(*self.op_args, **self.op_kwargs)
  File "/opt/airflow/dags/__pycache__/get_data_to_db.py", line 69, in insert_to_db
    (data['first_name'], data['last_name'], data['name'], data['location'], data['city'], data['country'], data['email'], data['phone'], data['picture']))
TypeError: list indices must be integers or slices, not str
[2025-07-21T15:04:58.715+0000] {taskinstance.py:1138} INFO - Marking task as FAILED. dag_id=put_data_to_db, task_id=insert_to_db, execution_date=20250721T150447, start_date=20250721T150458, end_date=20250721T150458
[2025-07-21T15:04:58.755+0000] {standard_task_runner.py:107} ERROR - Failed to execute job 12 for task insert_to_db (list indices must be integers or slices, not str; 458)
[2025-07-21T15:04:58.816+0000] {local_task_job_runner.py:234} INFO - Task exited with return code 1
[2025-07-21T15:04:58.889+0000] {taskinstance.py:3280} INFO - 0 downstream tasks scheduled from follow-on schedule check
