[2025-07-21T14:40:16.608+0000] {taskinstance.py:1956} INFO - Dependencies all met for dep_context=non-requeueable deps ti=<TaskInstance: put_data_to_db.insert_to_db manual__2025-07-21T14:40:14.931637+00:00 [queued]>
[2025-07-21T14:40:16.618+0000] {taskinstance.py:1956} INFO - Dependencies all met for dep_context=requeueable deps ti=<TaskInstance: put_data_to_db.insert_to_db manual__2025-07-21T14:40:14.931637+00:00 [queued]>
[2025-07-21T14:40:16.619+0000] {taskinstance.py:2170} INFO - Starting attempt 1 of 1
[2025-07-21T14:40:16.635+0000] {taskinstance.py:2191} INFO - Executing <Task(PythonOperator): insert_to_db> on 2025-07-21 14:40:14.931637+00:00
[2025-07-21T14:40:16.638+0000] {standard_task_runner.py:60} INFO - Started process 475 to run task
[2025-07-21T14:40:16.642+0000] {standard_task_runner.py:87} INFO - Running: ['***', 'tasks', 'run', 'put_data_to_db', 'insert_to_db', 'manual__2025-07-21T14:40:14.931637+00:00', '--job-id', '13', '--raw', '--subdir', 'DAGS_FOLDER/__pycache__/get_data_to_db.py', '--cfg-path', '/tmp/tmpd3i6eh28']
[2025-07-21T14:40:16.644+0000] {standard_task_runner.py:88} INFO - Job 13: Subtask insert_to_db
[2025-07-21T14:40:16.689+0000] {task_command.py:423} INFO - Running <TaskInstance: put_data_to_db.insert_to_db manual__2025-07-21T14:40:14.931637+00:00 [running]> on host d7e7273683d1
[2025-07-21T14:40:16.771+0000] {taskinstance.py:2480} INFO - Exporting env vars: AIRFLOW_CTX_DAG_OWNER='***' AIRFLOW_CTX_DAG_ID='put_data_to_db' AIRFLOW_CTX_TASK_ID='insert_to_db' AIRFLOW_CTX_EXECUTION_DATE='2025-07-21T14:40:14.931637+00:00' AIRFLOW_CTX_TRY_NUMBER='1' AIRFLOW_CTX_DAG_RUN_ID='manual__2025-07-21T14:40:14.931637+00:00'
[2025-07-21T14:40:16.784+0000] {taskinstance.py:2698} ERROR - Task failed with exception
Traceback (most recent call last):
  File "/home/airflow/.local/lib/python3.8/site-packages/airflow/models/taskinstance.py", line 433, in _execute_task
    result = execute_callable(context=context, **execute_callable_kwargs)
  File "/home/airflow/.local/lib/python3.8/site-packages/airflow/operators/python.py", line 199, in execute
    return_value = self.execute_callable()
  File "/home/airflow/.local/lib/python3.8/site-packages/airflow/operators/python.py", line 216, in execute_callable
    return self.python_callable(*self.op_args, **self.op_kwargs)
  File "/opt/airflow/dags/__pycache__/get_data_to_db.py", line 54, in insert_to_db
    conn = psycopg2.connect(
  File "/home/airflow/.local/lib/python3.8/site-packages/psycopg2/__init__.py", line 122, in connect
    conn = _connect(dsn, connection_factory=connection_factory, **kwasync)
psycopg2.OperationalError: connection to server at "localhost" (::1), port 5432 failed: Connection refused
	Is the server running on that host and accepting TCP/IP connections?
connection to server at "localhost" (127.0.0.1), port 5432 failed: Connection refused
	Is the server running on that host and accepting TCP/IP connections?

[2025-07-21T14:40:16.797+0000] {taskinstance.py:1138} INFO - Marking task as FAILED. dag_id=put_data_to_db, task_id=insert_to_db, execution_date=20250721T144014, start_date=20250721T144016, end_date=20250721T144016
[2025-07-21T14:40:16.809+0000] {standard_task_runner.py:107} ERROR - Failed to execute job 13 for task insert_to_db (connection to server at "localhost" (::1), port 5432 failed: Connection refused
	Is the server running on that host and accepting TCP/IP connections?
connection to server at "localhost" (127.0.0.1), port 5432 failed: Connection refused
	Is the server running on that host and accepting TCP/IP connections?
; 475)
[2025-07-21T14:40:16.815+0000] {local_task_job_runner.py:234} INFO - Task exited with return code 1
[2025-07-21T14:40:16.831+0000] {taskinstance.py:3280} INFO - 0 downstream tasks scheduled from follow-on schedule check
